<?xml version="1.0"?>
<robot name="differential_drive_robot" xmlns:xacro="http://www.ros.org/wiki/xacro">

    <!-- Base Link -->
    <link name="base_link">
        <inertial>
            <mass value="5.0"/>
            <origin xyz="0 0 0"/>
            <inertia ixx="0.1" iyy="0.1" izz="0.1" ixy="0" ixz="0" iyz="0"/>
        </inertial>
        <visual>
            <geometry>
                <box size="0.5 0.3 0.2"/>
            </geometry>
            <material name="blue"/>
        </visual>
        <collision>
            <geometry>
                <box size="0.5 0.3 0.2"/>
            </geometry>
        </collision>
    </link>

    <!-- Wheels -->
    <joint name="wheel_left_joint" type="continuous">
        <parent link="base_link"/>
        <child link="wheel_left"/>
        <origin xyz="0 0.15 0" rpy="0 0 0"/>
        <axis xyz="0 1 0"/>
    </joint>
    <link name="wheel_left">
        <visual>
            <geometry>
                <cylinder length="0.05" radius="0.1"/>
            </geometry>
            <material name="black"/>
        </visual>
        <collision>
            <geometry>
                <cylinder length="0.05" radius="0.1"/>
            </geometry>
        </collision>
    </link>

    <joint name="wheel_right_joint" type="continuous">
        <parent link="base_link"/>
        <child link="wheel_right"/>
        <origin xyz="0 -0.15 0" rpy="0 0 0"/>
        <axis xyz="0 1 0"/>
    </joint>
    <link name="wheel_right">
        <visual>
            <geometry>
                <cylinder length="0.05" radius="0.1"/>
            </geometry>
            <material name="black"/>
        </visual>
        <collision>
            <geometry>
                <cylinder length="0.05" radius="0.1"/>
            </geometry>
        </collision>
    </link>

    <!-- Depth Camera -->
    <link name="depth_camera">
        <visual>
            <geometry>
                <box size="0.1 0.05 0.05"/>
            </geometry>
            <material name="gray"/>
        </visual>
        <collision>
            <geometry>
                <box size="0.1 0.05 0.05"/>
            </geometry>
        </collision>
    </link>
    <joint name="depth_camera_joint" type="fixed">
        <parent link="base_link"/>
        <child link="depth_camera"/>
        <origin xyz="0.2 0 0.1" rpy="0 0 0"/>
    </joint>

    <!-- Gazebo Plugin for Differential Drive -->
    <gazebo>
        <plugin name="diff_drive_controller" filename="libgazebo_ros_diff_drive.so">
            <ros>
                <namespace>/</namespace>
                <remapping>
                    <from>cmd_vel</from>
                    <to>/cmd_vel</to>
                </remapping>
            </ros>
            <left_wheel>wheel_left_joint</left_wheel>
            <right_wheel>wheel_right_joint</right_wheel>
            <wheel_separation>0.3</wheel_separation>
            <wheel_diameter>0.2</wheel_diameter>
        </plugin>
    </gazebo>

</robot>
